Workbook

Sheet Read Me
A1: HOW TO USE THIS FILE
A3: WEEKLY
A4: 1. Paste the week's sales into Weekly Sales columns A–F (Week ending, Branch CPT/JHB/DBN, Item code, Article, spare, m² sold). Keep adding weeks below each other. Columns H–J fill themselves – never paste over them. Lines marked 'Not on stock sheet' are ignored (transport, cowhides, items with no stock line).
A5: 2. Add any stock moved between branches to Transfers.
A6: 3. New order sent to a supplier: add one line per item on Orders (PO number, order date, supplier, code, due month, branch, m², cost/m²).
A7: 4. Supplier invoice / delivery arrives: add one line per item on Stock Received (date, invoice no., the SAME PO number as on Orders, supplier, code, m², cost/m², branch). It adds to that branch's stock and closes the PO line. Never type received m² on the Orders tab – that column is a formula. A line closes once 90% or more has arrived (change on Settings); over-deliveries close it too.
A8: 5. Change "Stock as at" on the Settings tab to the date of the latest sales, then look at Dashboard → Reorder List, or filter Master Stock on STATUS.
A10: WHEN A NEW STOCK COUNT COMES IN
A11: Replace the m² on CPT Count / JHB Count / DBN Count, update the count dates on Settings, and clear Weekly Sales, Transfers and Stock Received.
A13: HOW THE NUMBERS WORK
A14: Available (per branch) = count m² + stock received − weekly sales for that branch + transfers in − transfers out.
A15: Avg selling m²/month = 6-month Sales History ÷ 6. Until that is loaded, it uses the average on the current CPT stock sheet.
... A28: COLOURS: blue text = typed input · black = formula · green = lookup from another tab · yellow fill = please check / fill in.

Sheet Dashboard
A1: AGS Stock Dashboard – leather hides & sides, all branches
A2: ="Stock as at "&TEXT(Settings!$B$13,"d mmmm yyyy")&" · everything on this page updates from Master Stock." -> Stock as at 9 October 2026 · everything on this page updates from Master Stock.
A4: STOCK AVAILABLE (m²) | G4: ON ORDER (m²) | L4: LINES BY STATUS
B5: CPT | C5: JHB | D5: DBN | E5: TOTAL | G5: Month | H5: For CPT | I5: For JHB | J5: Total | L5: Status | M5: Lines
A6: Hides | B6: =SUMIFS('Master Stock'!$E$5:$E$206,'Master Stock'!$C$5:$C$206,"Hide") -> 48961.5 | C6: =SUMIFS('Master Stock'!$F$5:$F$206,'Master Stock'!$C$5:$C$206,"Hide") -> 16197.83 | D6: =SUMIFS('Master Stock'!$G$5:$G$206,'Master Stock'!$C$5:$C$206,"Hide") -> 3132.66 | E6: =SUMIFS('Master Stock'!$H$5:$H$206,'Master Stock'!$C$5:$C$206,"Hide") -> 68291.99 | G6: ='Master Stock'!J4 -> 46296 | H6: =SUMIFS(Orders!$L:$L,Orders!$F:$F,">="&$G6,Orders!$F:$F,"<"&EDATE($G6,1),Orders!$G:$G,"CPT") -> 5680 | I6: =SUMIFS(Orders!$L:$L,Orders!$F:$F,">="&$G6,Orders!$F:$F,"<"&EDATE($G6,1),Orders!$G:$G,"JHB") -> 2200 | J6: =H6+I6 -> 7880 | L6: OUT - REORDER | M6: =COUNTIF('Master Stock'!$V$5:$V$206,L6) -> 0
A7: Sides | B7: =SUMIFS('Master Stock'!$E$5:$E$206,'Master Stock'!$C$5:$C$206,"Side") -> 14814 | C7: =SUMIFS('Master Stock'!$F$5:$F$206,'Master Stock'!$C$5:$C$206,"Side") -> 2107.75 | D7: =SUMIFS('Master Stock'!$G$5:$G$206,'Master Stock'!$C$5:$C$206,"Side") -> 981.61 | E7: =SUMIFS('Master Stock'!$H$5:$H$206,'Master Stock'!$C$5:$C$206,"Side") -> 17903.36 | G7: ='Master Stock'!K4 -> 46327 | H7: =SUMIFS(Orders!$L:$L,Orders!$F:$F,">="&$G7,Orders!$F:$F,"<"&EDATE($G7,1),Orders!$G:$G,"CPT") -> 17100 | I7: =SUMIFS(Orders!$L:$L,Orders!$F:$F,">="&$G7,Orders!$F:$F,"<"&EDATE($G7,1),Orders!$G:$G,"JHB") -> 8100 | J7: =H7+I7 -> 25200 | L7: REORDER | M7: =COUNTIF('Master Stock'!$V$5:$V$206,L7) -> 4
A8: Total | B8: =SUM(B6:B7) -> 63775.5 | C8: =SUM(C6:C7) -> 18305.58 | D8: =SUM(D6:D7) -> 4114.27 | E8: =SUM(E6:E7) -> 86195.35 | G8: ='Master Stock'!L4 -> 46357 | H8: =SUMIFS(Orders!$L:$L,Orders!$F:$F,">="&$G8,Orders!$F:$F,"<"&EDATE($G8,1),Orders!$G:$G,"CPT") -> 13300 | I8: =SUMIFS(Orders!$L:$L,Orders!$F:$F,">="&$G8,Orders!$F:$F,"<"&EDATE($G8,1),Orders!$G:$G,"JHB") -> 0 | J8: =H8+I8 -> 13300 | L8: OUT - ON ORDER | M8: =COUNTIF('Master Stock'!$V$5:$V$206,L8) -> 5
A9: Sold since count | E9: =SUM('Master Stock'!$I$5:$I$206) -> 5419.84 | G9: Later | J9: =SUM('Master Stock'!$M$5:$M$206) -> 0 | L9: LOW - ON ORDER | M9: =COUNTIF('Master Stock'!$V$5:$V$206,L9) -> 35
G10: Total | J10: =SUM('Master Stock'!$N$5:$N$206) -> 46380 | L10: OK | M10: =COUNTIF('Master Stock'!$V$5:$V$206,L10) -> 93
A11: Weekly sales not on stock sheet (m²) | E11: =SUMIFS('Weekly Sales'!$F:$F,'Weekly Sales'!$J:$J,"Not on stock sheet") -> 186.6 | G11: Value excl VAT | J11: =SUM(Orders!M5:M133) -> 12751784 | L11: SLOW MOVER | M11: =COUNTIF('Master Stock'!$V$5:$V$206,L11) -> 12
L12: NO BUFFER SET | M12: =COUNTIF('Master Stock'!$V$5:$V$206,L12) -> 10
L13: END OF RANGE | M13: =COUNTIF('Master Stock'!$V$5:$V$206,L13) -> 43
A16: REORDER LIST – biggest shortfall against buffer first (after counting stock on order)
A17: # | B17: Code | C17: Article | D17: Type | E17: Available m² | F17: On order m² | G17: Buffer m² | H17: Avg selling m²/month | I17: Short of buffer m² | J17: Months of cover | K17: Status
A18: 1 | B18: =IF($M18="","",INDEX('Master Stock'!$A$5:$A$206,$M18)) -> CAS004 | C18: =IF($M18="","",INDEX('Master Stock'!$B$5:$B$206,$M18)) -> CASTROL GREY | D18: =IF($M18="","",INDEX('Master Stock'!$C$5:$C$206,$M18)) -> Hide | E18: =IF($M18="","",INDEX('Master Stock'!$H$5:$H$206,$M18)) -> 156 | F18: =IF($M18="","",INDEX('Master Stock'!$N$5:$N$206,$M18)) -> 0 | G18: =IF($M18="","",INDEX('Master Stock'!$T$5:$T$206,$M18)) -> 200 | H18: =IF($M18="","",INDEX('Master Stock'!$Q$5:$Q$206,$M18)) -> 10 | I18: =IF($M18="","",INDEX('Master Stock'!$U$5:$U$206,$M18)) -> 44 | J18: =IF($M18="","",INDEX('Master Stock'!$S$5:$S$206,$M18)) -> 15.6 | K18: =IF($M18="","",INDEX('Master Stock'!$V$5:$V$206,$M18)) -> REORDER | M18: =IF(LARGE('Master Stock'!$X$5:$X$206,A18)>0,MATCH(LARGE('Master Stock'!$X$5:$X$206,A18),'Master Stock'!$X$5:$X$206,0),"") -> 29
A19: 2 | B19: =IF($M19="","",INDEX('Master Stock'!$A$5:$A$206,$M19)) -> TEX031 | C19: =IF($M19="","",INDEX('Master Stock'!$B$5:$B$206,$M19)) -> TEXAS COBALT | D19: =IF($M19="","",INDEX('Master Stock'!$C$5:$C$206,$M19)) -> Side | E19: =IF($M19="","",INDEX('Master Stock'!$H$5:$H$206,$M19)) -> 184.58 | F19: =IF($M19="","",INDEX('Master Stock'!$N$5:$N$206,$M19)) -> 0 | G19: =IF($M19="","",INDEX('Master Stock'!$T$5:$T$206,$M19)) -> 200 | H19: =IF($M19="","",INDEX('Master Stock'!$Q$5:$Q$206,$M19)) -> 35 | I19: =IF($M19="","",INDEX('Master Stock'!$U$5:$U$206,$M19)) -> 15.42 | J19: =IF($M19="","",INDEX('Master Stock'!$S$5:$S$206,$M19)) -> 5.2737143 | K19: =IF($M19="","",INDEX('Master Stock'!$V$5:$V$206,$M19)) -> REORDER | M19: =IF(LARGE('Master Stock'!$X$5:$X$206,A19)>0,MATCH(LARGE('Master Stock'!$X$5:$X$206,A19),'Master Stock'!$X$5:$X$206,0),"") -> 166
A20: 3 | B20: =IF($M20="","",INDEX('Master Stock'!$A$5:$A$206,$M20)) -> TEX029 | C20: =IF($M20="","",INDEX('Master Stock'!$B$5:$B$206,$M20)) -> TEXAS VIOLET | D20: =IF($M20="","",INDEX('Master Stock'!$C$5:$C$206,$M20)) -> Side | E20: =IF($M20="","",INDEX('Master Stock'!$H$5:$H$206,$M20)) -> 189.58 | F20: =IF($M20="","",INDEX('Master Stock'!$N$5:$N$206,$M20)) -> 0 | G20: =IF($M20="","",INDEX('Master Stock'!$T$5:$T$206,$M20)) -> 200 | H20: =IF($M20="","",INDEX('Master Stock'!$Q$5:$Q$206,$M20)) -> 30 | I20: =IF($M20="","",INDEX('Master Stock'!$U$5:$U$206,$M20)) -> 10.42 | J20: =IF($M20="","",INDEX('Master Stock'!$S$5:$S$206,$M20)) -> 6.3193333 | K20: =IF($M20="","",INDEX('Master Stock'!$V$5:$V$206,$M20)) -> REORDER | M20: =IF(LARGE('Master Stock'!$X$5:$X$206,A20)>0,MATCH(LARGE('Master Stock'!$X$5:$X$206,A20),'Master Stock'!$X$5:$X$206,0),"") -> 174
A21: 4 | B21: =IF($M21="","",INDEX('Master Stock'!$A$5:$A$206,$M21)) -> SOR002 | C21: =IF($M21="","",INDEX('Master Stock'!$B$5:$B$206,$M21)) -> SORRENTO GREY | D21: =IF($M21="","",INDEX('Master Stock'!$C$5:$C$206,$M21)) -> Hide | E21: =IF($M21="","",INDEX('Master Stock'!$H$5:$H$206,$M21)) -> 97.01 | F21: =IF($M21="","",INDEX('Master Stock'!$N$5:$N$206,$M21)) -> 0 | G21: =IF($M21="","",INDEX('Master Stock'!$T$5:$T$206,$M21)) -> 100 | H21: =IF($M21="","",INDEX('Master Stock'!$Q$5:$Q$206,$M21)) -> 0 | I21: =IF($M21="","",INDEX('Master Stock'!$U$5:$U$206,$M21)) -> 2.99 | J21: =IF($M21="","",INDEX('Master Stock'!$S$5:$S$206,$M21)) | K21: =IF($M21="","",INDEX('Master Stock'!$V$5:$V$206,$M21)) -> REORDER | M21: =IF(LARGE('Master Stock'!$X$5:$X$206,A21)>0,MATCH(LARGE('Master Stock'!$X$5:$X$206,A21),'Master Stock'!$X$5:$X$206,0),"") -> 107
A22: 5 | B22: =IF($M22="","",INDEX('Master Stock'!$A$5:$A$206,$M22)) | C22: =IF($M22="","",INDEX('Master Stock'!$B$5:$B$206,$M22)) | D22: =IF($M22="","",INDEX('Master Stock'!$C$5:$C$206,$M22)) | E22: =IF($M22="","",INDEX('Master Stock'!$H$5:$H$206,$M22)) | F22: =IF($M22="","",INDEX('Master Stock'!$N$5:$N$206,$M22)) | G22: =IF($M22="","",INDEX('Master Stock'!$T$5:$T$206,$M22)) | H22: =IF($M22="","",INDEX('Master Stock'!$Q$5:$Q$206,$M22)) | I22: =IF($M22="","",INDEX('Master Stock'!$U$5:$U$206,$M22)) | J22: =IF($M22="","",INDEX('Master Stock'!$S$5:$S$206,$M22)) | K22: =IF($M22="","",INDEX('Master Stock'!$V$5:$V$206,$M22)) | M22: =IF(LARGE('Master Stock'!$X$5:$X$206,A22)>0,MATCH(LARGE('Master Stock'!$X$5:$X$206,A22),'Master Stock'!$X$5:$X$206,0),"")
A23: 6 | B23: =IF($M23="","",INDEX('Master Stock'!$A$5:$A$206,$M23)) | C23: =IF($M23="","",INDEX('Master Stock'!$B$5:$B$206,$M23)) | D23: =IF($M23="","",INDEX('Master Stock'!$C$5:$C$206,$M23)) | E23: =IF($M23="","",INDEX('Master Stock'!$H$5:$H$206,$M23)) | F23: =IF($M23="","",INDEX('Master Stock'!$N$5:$N$206,$M23)) | G23: =IF($M23="","",INDEX('Master Stock'!$T$5:$T$206,$M23)) | H23: =IF($M23="","",INDEX('Master Stock'!$Q$5:$Q$206,$M23)) | I23: =IF($M23="","",INDEX('Master Stock'!$U$5:$U$206,$M23)) | J23: =IF($M23="","",INDEX('Master Stock'!$S$5:$S$206,$M23)) | K23: =IF($M23="","",INDEX('Master Stock'!$V$5:$V$206,$M23)) | M23: =IF(LARGE('Master Stock'!$X$5:$X$206,A23)>0,MATCH(LARGE('Master Stock'!$X$5:$X$206,A23),'Master Stock'!$X$5:$X$206,0),"")
A24: 7 | B24: =IF($M24="","",INDEX('Master Stock'!$A$5:$A$206,$M24)) | C24: =IF($M24="","",INDEX('Master Stock'!$B$5:$B$206,$M24)) | D24: =IF($M24="","",INDEX('Master Stock'!$C$5:$C$206,$M24)) | E24: =IF($M24="","",INDEX('Master Stock'!$H$5:$H$206,$M24)) | F24: =IF($M24="","",INDEX('Master Stock'!$N$5:$N$206,$M24)) | G24: =IF($M24="","",INDEX('Master Stock'!$T$5:$T$206,$M24)) | H24: =IF($M24="","",INDEX('Master Stock'!$Q$5:$Q$206,$M24)) | I24: =IF($M24="","",INDEX('Master Stock'!$U$5:$U$206,$M24)) | J24: =IF($M24="","",INDEX('Master Stock'!$S$5:$S$206,$M24)) | K24: =IF($M24="","",INDEX('Master Stock'!$V$5:$V$206,$M24)) | M24: =IF(LARGE('Master Stock'!$X$5:$X$206,A24)>0,MATCH(LARGE('Master Stock'!$X$5:$X$206,A24),'Master Stock'!$X$5:$X$206,0),"")
A25: 8 | B25: =IF($M25="","",INDEX('Master Stock'!$A$5:$A$206,$M25)) | C25: =IF($M25="","",INDEX('Master Stock'!$B$5:$B$206,$M25)) | D25: =IF($M25="","",INDEX('Master Stock'!$C$5:$C$206,$M25)) | E25: =IF($M25="","",INDEX('Master Stock'!$H$5:$H$206,$M25)) | F25: =IF($M25="","",INDEX('Master Stock'!$N$5:$N$206,$M25)) | G25: =IF($M25="","",INDEX('Master Stock'!$T$5:$T$206,$M25)) | H25: =IF($M25="","",INDEX('Master Stock'!$Q$5:$Q$206,$M25)) | I25: =IF($M25="","",INDEX('Master Stock'!$U$5:$U$206,$M25)) | J25: =IF($M25="","",INDEX('Master Stock'!$S$5:$S$206,$M25)) | K25: =IF($M25="","",INDEX('Master Stock'!$V$5:$V$206,$M25)) | M25: =IF(LARGE('Master Stock'!$X$5:$X$206,A25)>0,MATCH(LARGE('Master Stock'!$X$5:$X$206,A25),'Master Stock'!$X$5:$X$206,0),"")
A26: 9 | B26: =IF($M26="","",INDEX('Master Stock'!$A$5:$A$206,$M26)) | C26: =IF($M26="","",INDEX('Master Stock'!$B$5:$B$206,$M26)) | D26: =IF($M26="","",INDEX('Master Stock'!$C$5:$C$206,$M26)) | E26: =IF($M26="","",INDEX('Master Stock'!$H$5:$H$206,$M26)) | F26: =IF($M26="","",INDEX('Master Stock'!$N$5:$N$206,$M26)) | G26: =IF($M26="","",INDEX('Master Stock'!$T$5:$T$206,$M26)) | H26: =IF($M26="","",INDEX('Master Stock'!$Q$5:$Q$206,$M26)) | I26: =IF($M26="","",INDEX('Master Stock'!$U$5:$U$206,$M26)) | J26: =IF($M26="","",INDEX('Master Stock'!$S$5:$S$206,$M26)) | K26: =IF($M26="","",INDEX('Master Stock'!$V$5:$V$206,$M26)) | M26: =IF(LARGE('Master Stock'!$X$5:$X$206,A26)>0,MATCH(LARGE('Master Stock'!$X$5:$X$206,A26),'Master Stock'!$X$5:$X$206,0),"")
A27: 10 | B27: =IF($M27="","",INDEX('Master Stock'!$A$5:$A$206,$M27)) | C27: =IF($M27="","",INDEX('Master Stock'!$B$5:$B$206,$M27)) | D27: =IF($M27="","",INDEX('Master Stock'!$C$5:$C$206,$M27)) | E27: =IF($M27="","",INDEX('Master Stock'!$H$5:$H$206,$M27)) | F27: =IF($M27="","",INDEX('Master Stock'!$N$5:$N$206,$M27)) | G27: =IF($M27="","",INDEX('Master Stock'!$T$5:$T$206,$M27)) | H27: =IF($M27="","",INDEX('Master Stock'!$Q$5:$Q$206,$M27)) | I27: =IF($M27="","",INDEX('Master Stock'!$U$5:$U$206,$M27)) | J27: =IF($M27="","",INDEX('Master Stock'!$S$5:$S$206,$M27)) | K27: =IF($M27="","",INDEX('Master Stock'!$V$5:$V$206,$M27)) | M27: =IF(LARGE('Master Stock'!$X$5:$X$206,A27)>0,MATCH(LARGE('Master Stock'!$X$5:$X$206,A27),'Master Stock'!$X$5:$X$206,0),"")
A28: 11 | B28: =IF($M28="","",INDEX('Master Stock'!$A$5:$A$206,$M28)) | C28: =IF($M28="","",INDEX('Master Stock'!$B$5:$B$206,$M28)) | D28: =IF($M28="","",INDEX('Master Stock'!$C$5:$C$206,$M28)) | E28: =IF($M28="","",INDEX('Master Stock'!$H$5:$H$206,$M28)) | F28: =IF($M28="","",INDEX('Master Stock'!$N$5:$N$206,$M28)) | G28: =IF($M28="","",INDEX('Master Stock'!$T$5:$T$206,$M28)) | H28: =IF($M28="","",INDEX('Master Stock'!$Q$5:$Q$206,$M28)) | I28: =IF($M28="","",INDEX('Master Stock'!$U$5:$U$206,$M28)) | J28: =IF($M28="","",INDEX('Master Stock'!$S$5:$S$206,$M28)) | K28: =IF($M28="","",INDEX('Master Stock'!$V$5:$V$206,$M28)) | M28: =IF(LARGE('Master Stock'!$X$5:$X$206,A28)>0,MATCH(LARGE('Master Stock'!$X$5:$X$206,A28),'Master Stock'!$X$5:$X$206,0),"")
A29: 12 | B29: =IF($M29="","",INDEX('Master Stock'!$A$5:$A$206,$M29)) | C29: =IF($M29="","",INDEX('Master Stock'!$B$5:$B$206,$M29)) | D29: =IF($M29="","",INDEX('Master Stock'!$C$5:$C$206,$M29)) | E29: =IF($M29="","",INDEX('Master Stock'!$H$5:$H$206,$M29)) | F29: =IF($M29="","",INDEX('Master Stock'!$N$5:$N$206,$M29)) | G29: =IF($M29="","",INDEX('Master Stock'!$T$5:$T$206,$M29)) | H29: =IF($M29="","",INDEX('Master Stock'!$Q$5:$Q$206,$M29)) | I29: =IF($M29="","",INDEX('Master Stock'!$U$5:$U$206,$M29)) | J29: =IF($M29="","",INDEX('Master Stock'!$S$5:$S$206,$M29)) | K29: =IF($M29="","",INDEX('Master Stock'!$V$5:$V$206,$M29)) | M29: =IF(LARGE('Master Stock'!$X$5:$X$206,A29)>0,MATCH(LARGE('Master Stock'!$X$5:$X$206,A29),'Master Stock'!$X$5:$X$206,0),"")
... A57: 40 | B57: =IF($M57="","",INDEX('Master Stock'!$A$5:$A$206,$M57)) | C57: =IF($M57="","",INDEX('Master Stock'!$B$5:$B$206,$M57)) | D57: =IF($M57="","",INDEX('Master Stock'!$C$5:$C$206,$M57)) | E57: =IF($M57="","",INDEX('Master Stock'!$H$5:$H$206,$M57)) | F57: =IF($M57="","",INDEX('Master Stock'!$N$5:$N$206,$M57)) | G57: =IF($M57="","",INDEX('Master Stock'!$T$5:$T$206,$M57)) | H57: =IF($M57="","",INDEX('Master Stock'!$Q$5:$Q$206,$M57)) | I57: =IF($M57="","",INDEX('Master Stock'!$U$5:$U$206,$M57)) | J57: =IF($M57="","",INDEX('Master Stock'!$S$5:$S$206,$M57)) | K57: =IF($M57="","",INDEX('Master Stock'!$V$5:$V$206,$M57)) | M57: =IF(LARGE('Master Stock'!$X$5:$X$206,A57)>0,MATCH(LARGE('Master Stock'!$X$5:$X$206,A57),'Master Stock'!$X$5:$X$206,0),"")

Sheet Master Stock
A1: AGS Universal Stock Sheet – all branches (leather hides & sides)
A2: ="Stock as at "&TEXT(Settings!$B$13,"d mmmm yyyy")&" · CPT count 8 Oct, JHB & DBN count 30 Sep, plus stock received, less weekly sales, ± transfers. Blue = input, black = formula." -> Stock as at 9 October 2026 · CPT count 8 Oct, JHB & DBN count 30 Sep, plus stock received, less weekly sales, ± transfers. Blue = input, black = formula.
A4: Code | B4: Article | C4: Type | D4: Range | E4: CPT m² | F4: JHB m² | G4: DBN m² | H4: TOTAL AVAILABLE m² | I4: Sold since count m² | J4: 46296 | K4: 46327 | L4: 46357 | M4: On order later | N4: Total on order m² | O4: Available + on order | P4: Avg/month (current sheet) | Q4: Avg selling m²/month | R4: Avg source | S4: Months of cover | T4: Buffer m² | U4: Short of buffer m² | V4: STATUS | W4: Notes | X4: rank (helper)
A5: GAZ001 | B5: GAZELLE OXBLOOD | C5: Hide | D5: Active | E5: =SUMIFS('CPT Count'!$D:$D,'CPT Count'!$A:$A,$A5)-SUMIFS('Weekly Sales'!$F:$F,'Weekly Sales'!$H:$H,$A5,'Weekly Sales'!$I:$I,"CPT")+SUMIFS(Transfers!$F:$F,Transfers!$C:$C,$A5,Transfers!$J:$J,"CPT")-SUMIFS(Transfers!$F:$F,Transfers!$C:$C,$A5,Transfers!$I:$I,"CPT",Transfers!$H:$H,"<>Y")+SUMIFS('Stock Received'!$I:$I,'Stock Received'!$E:$E,$A5,'Stock Received'!$L:$L,"CPT") -> 722.41 | F5: =SUMIFS('JHB Count'!$E:$E,'JHB Count'!$F:$F,$A5)-SUMIFS('Weekly Sales'!$F:$F,'Weekly Sales'!$H:$H,$A5,'Weekly Sales'!$I:$I,"JHB")+SUMIFS(Transfers!$F:$F,Transfers!$C:$C,$A5,Transfers!$J:$J,"JHB")-SUMIFS(Transfers!$F:$F,Transfers!$C:$C,$A5,Transfers!$I:$I,"JHB",Transfers!$H:$H,"<>Y")+SUMIFS('Stock Received'!$I:$I,'Stock Received'!$E:$E,$A5,'Stock Received'!$L:$L,"JHB") -> 44 | G5: =SUMIFS('DBN Count'!$D:$D,'DBN Count'!$E:$E,$A5)-SUMIFS('Weekly Sales'!$F:$F,'Weekly Sales'!$H:$H,$A5,'Weekly Sales'!$I:$I,"DBN")+SUMIFS(Transfers!$F:$F,Transfers!$C:$C,$A5,Transfers!$J:$J,"DBN")-SUMIFS(Transfers!$F:$F,Transfers!$C:$C,$A5,Transfers!$I:$I,"DBN",Transfers!$H:$H,"<>Y")+SUMIFS('Stock Received'!$I:$I,'Stock Received'!$E:$E,$A5,'Stock Received'!$L:$L,"DBN") -> 20.15 | H5: =E5+F5+G5 -> 786.56 | I5: =SUMIFS('Weekly Sales'!$F:$F,'Weekly Sales'!$H:$H,$A5) -> 8.16 | J5: =SUMIFS(Orders!$L:$L,Orders!$D:$D,$A5,Orders!$F:$F,">="&J$4,Orders!$F:$F,"<"&EDATE(J$4,1)) -> 0 | K5: =SUMIFS(Orders!$L:$L,Orders!$D:$D,$A5,Orders!$F:$F,">="&K$4,Orders!$F:$F,"<"&EDATE(K$4,1)) -> 0 | L5: =SUMIFS(Orders!$L:$L,Orders!$D:$D,$A5,Orders!$F:$F,">="&L$4,Orders!$F:$F,"<"&EDATE(L$4,1)) -> 0 | M5: =N5-J5-K5-L5 -> 0 | N5: =SUMIFS(Orders!$L:$L,Orders!$D:$D,$A5) -> 0 | O5: =H5+N5 -> 786.56 | P5: 100 | Q5: =IF(SUMIFS('Sales History'!$E:$E,'Sales History'!$G:$G,$A5)>0,SUMIFS('Sales History'!$E:$E,'Sales History'!$G:$G,$A5)/Settings!$B$4,N(P5)) -> 100 | R5: =IF(SUMIFS('Sales History'!$E:$E,'Sales History'!$G:$G,$A5)>0,"6-month history",IF(N(P5)>0,"Current sheet","No sales data")) -> Current sheet | S5: =IF(Q5>0,H5/Q5,"") -> 7.8656 | T5: 300 | U5: =IF(T5="","",MAX(0,T5-O5)) -> 0 | V5: =IF(D5="End of range","END OF RANGE",IF(T5="","NO BUFFER SET",IF(H5<=0,IF(O5<T5,"OUT - REORDER","OUT - ON ORDER"),IF(O5<T5,"REORDER",IF(H5<T5,"LOW - ON ORDER",IF(AND(S5<>"",N(S5)>Settings!$B$5),"SLOW MOVER","OK")))))) -> OK | X5: =IF(OR(D5="End of range",U5=""),0,IF(N(U5)>0,U5+ROW()/1000000,0)) -> 0
A6: GAZ010 | B6: GAZELLE MOCCA | C6: Hide | D6: Active | E6: =SUMIFS('CPT Count'!$D:$D,'CPT Count'!$A:$A,$A6)-SUMIFS('Weekly Sales'!$F:$F,'Weekly Sales'!$H:$H,$A6,'Weekly Sales'!$I:$I,"CPT")+SUMIFS(Transfers!$F:$F,Transfers!$C:$C,$A6,Transfers!$J:$J,"CPT")-SUMIFS(Transfers!$F:$F,Transfers!$C:$C,$A6,Transfers!$I:$I,"CPT",Transfers!$H:$H,"<>Y")+SUMIFS('Stock Received'!$I:$I,'Stock Received'!$E:$E,$A6,'Stock Received'!$L:$L,"CPT") -> 558.18 | F6: =SUMIFS('JHB Count'!$E:$E,'JHB Count'!$F:$F,$A6)-SUMIFS('Weekly Sales'!$F:$F,'Weekly Sales'!$H:$H,$A6,'Weekly Sales'!$I:$I,"JHB")+SUMIFS(Transfers!$F:$F,Transfers!$C:$C,$A6,Transfers!$J:$J,"JHB")-SUMIFS(Transfers!$F:$F,Transfers!$C:$C,$A6,Transfers!$I:$I,"JHB",Transfers!$H:$H,"<>Y")+SUMIFS('Stock Received'!$I:$I,'Stock Received'!$E:$E,$A6,'Stock Received'!$L:$L,"JHB") -> 64 | G6: =SUMIFS('DBN Count'!$D:$D,'DBN Count'!$E:$E,$A6)-SUMIFS('Weekly Sales'!$F:$F,'Weekly Sales'!$H:$H,$A6,'Weekly Sales'!$I:$I,"DBN")+SUMIFS(Transfers!$F:$F,Transfers!$C:$C,$A6,Transfers!$J:$J,"DBN")-SUMIFS(Transfers!$F:$F,Transfers!$C:$C,$A6,Transfers!$I:$I,"DBN",Transfers!$H:$H,"<>Y")+SUMIFS('Stock Received'!$I:$I,'Stock Received'!$E:$E,$A6,'Stock Received'!$L:$L,"DBN") -> 24.59 | H6: =E6+F6+G6 -> 646.77 | I6: =SUMIFS('Weekly Sales'!$F:$F,'Weekly Sales'!$H:$H,$A6) -> 48.01 | J6: =SUMIFS(Orders!$L:$L,Orders!$D:$D,$A6,Orders!$F:$F,">="&J$4,Orders!$F:$F,"<"&EDATE(J$4,1)) -> 0 | K6: =SUMIFS(Orders!$L:$L,Orders!$D:$D,$A6,Orders!$F:$F,">="&K$4,Orders!$F:$F,"<"&EDATE(K$4,1)) -> 0 | L6: =SUMIFS(Orders!$L:$L,Orders!$D:$D,$A6,Orders!$F:$F,">="&L$4,Orders!$F:$F,"<"&EDATE(L$4,1)) -> 0 | M6: =N6-J6-K6-L6 -> 0 | N6: =SUMIFS(Orders!$L:$L,Orders!$D:$D,$A6) -> 0 | O6: =H6+N6 -> 646.77 | P6: 110 | Q6: =IF(SUMIFS('Sales History'!$E:$E,'Sales History'!$G:$G,$A6)>0,SUMIFS('Sales History'!$E:$E,'Sales History'!$G:$G,$A6)/Settings!$B$4,N(P6)) -> 110 | R6: =IF(SUMIFS('Sales History'!$E:$E,'Sales History'!$G:$G,$A6)>0,"6-month history",IF(N(P6)>0,"Current sheet","No sales data")) -> Current sheet | S6: =IF(Q6>0,H6/Q6,"") -> 5.8797273 | T6: 300 | U6: =IF(T6="","",MAX(0,T6-O6)) -> 0 | V6: =IF(D6="End of range","END OF RANGE",IF(T6="","NO BUFFER SET",IF(H6<=0,IF(O6<T6,"OUT - REORDER","OUT - ON ORDER"),IF(O6<T6,"REORDER",IF(H6<T6,"LOW - ON ORDER",IF(AND(S6<>"",N(S6)>Settings!$B$5),"SLOW MOVER","OK")))))) -> OK | X6: =IF(OR(D6="End of range",U6=""),0,IF(N(U6)>0,U6+ROW()/1000000,0)) -> 0
A7: GAZ006 | B7: GAZELLE BLACK | C7: Hide | D7: Active | E7: =SUMIFS('CPT Count'!$D:$D,'CPT Count'!$A:$A,$A7)-SUMIFS('Weekly Sales'!$F:$F,'Weekly Sales'!$H:$H,$A7,'Weekly Sales'!$I:$I,"CPT")+SUMIFS(Transfers!$F:$F,Transfers!$C:$C,$A7,Transfers!$J:$J,"CPT")-SUMIFS(Transfers!$F:$F,Transfers!$C:$C,$A7,Transfers!$I:$I,"CPT",Transfers!$H:$H,"<>Y")+SUMIFS('Stock Received'!$I:$I,'Stock Received'!$E:$E,$A7,'Stock Received'!$L:$L,"CPT") -> 1174.19 | F7: =SUMIFS('JHB Count'!$E:$E,'JHB Count'!$F:$F,$A7)-SUMIFS('Weekly Sales'!$F:$F,'Weekly Sales'!$H:$H,$A7,'Weekly Sales'!$I:$I,"JHB")+SUMIFS(Transfers!$F:$F,Transfers!$C:$C,$A7,Transfers!$J:$J,"JHB")-SUMIFS(Transfers!$F:$F,Transfers!$C:$C,$A7,Transfers!$I:$I,"JHB",Transfers!$H:$H,"<>Y")+SUMIFS('Stock Received'!$I:$I,'Stock Received'!$E:$E,$A7,'Stock Received'!$L:$L,"JHB") -> 107.05 | G7: =SUMIFS('DBN Count'!$D:$D,'DBN Count'!$E:$E,$A7)-SUMIFS('Weekly Sales'!$F:$F,'Weekly Sales'!$H:$H,$A7,'Weekly Sales'!$I:$I,"DBN")+SUMIFS(Transfers!$F:$F,Transfers!$C:$C,$A7,Transfers!$J:$J,"DBN")-SUMIFS(Transfers!$F:$F,Transfers!$C:$C,$A7,Transfers!$I:$I,"DBN",Transfers!$H:$H,"<>Y")+SUMIFS('Stock Received'!$I:$I,'Stock Received'!$E:$E,$A7,'Stock Received'!$L:$L,"DBN") -> 137.85 | H7: =E7+F7+G7 -> 1419.09 | I7: =SUMIFS('Weekly Sales'!$F:$F,'Weekly Sales'!$H:$H,$A7) -> 33.43 | J7: =SUMIFS(Orders!$L:$L,Orders!$D:$D,$A7,Orders!$F:$F,">="&J$4,Orders!$F:$F,"<"&EDATE(J$4,1)) -> 0 | K7: =SUMIFS(Orders!$L:$L,Orders!$D:$D,$A7,Orders!$F:$F,">="&K$4,Orders!$F:$F,"<"&EDATE(K$4,1)) -> 0 | L7: =SUMIFS(Orders!$L:$L,Orders!$D:$D,$A7,Orders!$F:$F,">="&L$4,Orders!$F:$F,"<"&EDATE(L$4,1)) -> 500 | M7: =N7-J7-K7-L7 -> 0 | N7: =SUMIFS(Orders!$L:$L,Orders!$D:$D,$A7) -> 500 | O7: =H7+N7 -> 1919.09 | P7: 375 | Q7: =IF(SUMIFS('Sales History'!$E:$E,'Sales History'!$G:$G,$A7)>0,SUMIFS('Sales History'!$E:$E,'Sales History'!$G:$G,$A7)/Settings!$B$4,N(P7)) -> 375 | R7: =IF(SUMIFS('Sales History'!$E:$E,'Sales History'!$G:$G,$A7)>0,"6-month history",IF(N(P7)>0,"Current sheet","No sales data")) -> Current sheet | S7: =IF(Q7>0,H7/Q7,"") -> 3.78424 | T7: 500 | U7: =IF(T7="","",MAX(0,T7-O7)) -> 0 | V7: =IF(D7="End of range","END OF RANGE",IF(T7="","NO BUFFER SET",IF(H7<=0,IF(O7<T7,"OUT - REORDER","OUT - ON ORDER"),IF(O7<T7,"REORDER",IF(H7<T7,"LOW - ON ORDER",IF(AND(S7<>"",N(S7)>Settings!$B$5),"SLOW MOVER","OK")))))) -> OK | X7: =IF(OR(D7="End of range",U7=""),0,IF(N(U7)>0,U7+ROW()/1000000,0)) -> 0
A8: GAZ007 | B8: GAZELLE RED | C8: Hide | D8: Active | E8: =SUMIFS('CPT Count'!$D:$D,'CPT Count'!$A:$A,$A8)-SUMIFS('Weekly Sales'!$F:$F,'Weekly Sales'!$H:$H,$A8,'Weekly Sales'!$I:$I,"CPT")+SUMIFS(Transfers!$F:$F,Transfers!$C:$C,$A8,Transfers!$J:$J,"CPT")-SUMIFS(Transfers!$F:$F,Transfers!$C:$C,$A8,Transfers!$I:$I,"CPT",Transfers!$H:$H,"<>Y")+SUMIFS('Stock Received'!$I:$I,'Stock Received'!$E:$E,$A8,'Stock Received'!$L:$L,"CPT") -> 351 | F8: =SUMIFS('JHB Count'!$E:$E,'JHB Count'!$F:$F,$A8)-SUMIFS('Weekly Sales'!$F:$F,'Weekly Sales'!$H:$H,$A8,'Weekly Sales'!$I:$I,"JHB")+SUMIFS(Transfers!$F:$F,Transfers!$C:$C,$A8,Transfers!$J:$J,"JHB")-SUMIFS(Transfers!$F:$F,Transfers!$C:$C,$A8,Transfers!$I:$I,"JHB",Transfers!$H:$H,"<>Y")+SUMIFS('Stock Received'!$I:$I,'Stock Received'!$E:$E,$A8,'Stock Received'!$L:$L,"JHB") -> 60 | G8: =SUMIFS('DBN Count'!$D:$D,'DBN Count'!$E:$E,$A8)-SUMIFS('Weekly Sales'!$F:$F,'Weekly Sales'!$H:$H,$A8,'Weekly Sales'!$I:$I,"DBN")+SUMIFS(Transfers!$F:$F,Transfers!$C:$C,$A8,Transfers!$J:$J,"DBN")-SUMIFS(Transfers!$F:$F,Transfers!$C:$C,$A8,Transfers!$I:$I,"DBN",Transfers!$H:$H,"<>Y")+SUMIFS('Stock Received'!$I:$I,'Stock Received'!$E:$E,$A8,'Stock Received'!$L:$L,"DBN") -> 21.47 | H8: =E8+F8+G8 -> 432.47 | I8: =SUMIFS('Weekly Sales'!$F:$F,'Weekly Sales'!$H:$H,$A8) -> 0 | J8: =SUMIFS(Orders!$L:$L,Orders!$D:$D,$A8,Orders!$F:$F,">="&J$4,Orders!$F:$F,"<"&EDATE(J$4,1)) -> 0 | K8: =SUMIFS(Orders!$L:$L,Orders!$D:$D,$A8,Orders!$F:$F,">="&K$4,Orders!$F:$F,"<"&EDATE(K$4,1)) -> 0 | L8: =SUMIFS(Orders!$L:$L,Orders!$D:$D,$A8,Orders!$F:$F,">="&L$4,Orders!$F:$F,"<"&EDATE(L$4,1)) -> 0 | M8: =N8-J8-K8-L8 -> 0 | N8: =SUMIFS(Orders!$L:$L,Orders!$D:$D,$A8) -> 0 | O8: =H8+N8 -> 432.47 | P8: 50 | Q8: =IF(SUMIFS('Sales History'!$E:$E,'Sales History'!$G:$G,$A8)>0,SUMIFS('Sales History'!$E:$E,'Sales History'!$G:$G,$A8)/Settings!$B$4,N(P8)) -> 50 | R8: =IF(SUMIFS('Sales History'!$E:$E,'Sales History'!$G:$G,$A8)>0,"6-month history",IF(N(P8)>0,"Current sheet","No sales data")) -> Current sheet | S8: =IF(Q8>0,H8/Q8,"") -> 8.6494 | T8: 300 | U8: =IF(T8="","",MAX(0,T8-O8)) -> 0 | V8: =IF(D8="End of range","END OF RANGE",IF(T8="","NO BUFFER SET",IF(H8<=0,IF(O8<T8,"OUT - REORDER","OUT - ON ORDER"),IF(O8<T8,"REORDER",IF(H8<T8,"LOW - ON ORDER",IF(AND(S8<>"",N(S8)>Settings!$B$5),"SLOW MOVER","OK")))))) -> OK | X8: =IF(OR(D8="End of range",U8=""),0,IF(N(U8)>0,U8+ROW()/1000000,0)) -> 0
A9: GAZ005 | B9: GAZELLE NAVY | C9: Hide | D9: Active | E9: =SUMIFS('CPT Count'!$D:$D,'CPT Count'!$A:$A,$A9)-SUMIFS('Weekly Sales'!$F:$F,'Weekly Sales'!$H:$H,$A9,'Weekly Sales'!$I:$I,"CPT")+SUMIFS(Transfers!$F:$F,Transfers!$C:$C,$A9,Transfers!$J:$J,"CPT")-SUMIFS(Transfers!$F:$F,Transfers!$C:$C,$A9,Transfers!$I:$I,"CPT",Transfers!$H:$H,"<>Y")+SUMIFS('Stock Received'!$I:$I,'Stock Received'!$E:$E,$A9,'Stock Received'!$L:$L,"CPT") -> 595.35 | F9: =SUMIFS('JHB Count'!$E:$E,'JHB Count'!$F:$F,$A9)-SUMIFS('Weekly Sales'!$F:$F,'Weekly Sales'!$H:$H,$A9,'Weekly Sales'!$I:$I,"JHB")+SUMIFS(Transfers!$F:$F,Transfers!$C:$C,$A9,Transfers!$J:$J,"JHB")-SUMIFS(Transfers!$F:$F,Transfers!$C:$C,$A9,Transfers!$I:$I,"JHB",Transfers!$H:$H,"<>Y")+SUMIFS('Stock Received'!$I:$I,'Stock Received'!$E:$E,$A9,'Stock Received'!$L:$L,"JHB") -> 36 | G9: =SUMIFS('DBN Count'!$D:$D,'DBN Count'!$E:$E,$A9)-SUMIFS('Weekly Sales'!$F:$F,'Weekly Sales'!$H:$H,$A9,'Weekly Sales'!$I:$I,"DBN")+SUMIFS(Transfers!$F:$F,Transfers!$C:$C,$A9,Transfers!$J:$J,"DBN")-SUMIFS(Transfers!$F:$F,Transfers!$C:$C,$A9,Transfers!$I:$I,"DBN",Transfers!$H:$H,"<>Y")+SUMIFS('Stock Received'!$I:$I,'Stock Received'!$E:$E,$A9,'Stock Received'!$L:$L,"DBN") -> 23.29 | H9: =E9+F9+G9 -> 654.64 | I9: =SUMIFS('Weekly Sales'!$F:$F,'Weekly Sales'!$H:$H,$A9) -> 3.65 | J9: =SUMIFS(Orders!$L:$L,Orders!$D:$D,$A9,Orders!$F:$F,">="&J$4,Orders!$F:$F,"<"&EDATE(J$4,1)) -> 0 | K9: =SUMIFS(Orders!$L:$L,Orders!$D:$D,$A9,Orders!$F:$F,">="&K$4,Orders!$F:$F,"<"&EDATE(K$4,1)) -> 0 | L9: =SUMIFS(Orders!$L:$L,Orders!$D:$D,$A9,Orders!$F:$F,">="&L$4,Orders!$F:$F,"<"&EDATE(L$4,1)) -> 0 | M9: =N9-J9-K9-L9 -> 0 | N9: =SUMIFS(Orders!$L:$L,Orders!$D:$D,$A9) -> 0 | O9: =H9+N9 -> 654.64 | P9: 110 | Q9: =IF(SUMIFS('Sales History'!$E:$E,'Sales History'!$G:$G,$A9)>0,SUMIFS('Sales History'!$E:$E,'Sales History'!$G:$G,$A9)/Settings!$B$4,N(P9)) -> 110 | R9: =IF(SUMIFS('Sales History'!$E:$E,'Sales History'!$G:$G,$A9)>0,"6-month history",IF(N(P9)>0,"Current sheet","No sales data")) -> Current sheet | S9: =IF(Q9>0,H9/Q9,"") -> 5.9512727 | T9: 300 | U9: =IF(T9="","",MAX(0,T9-O9)) -> 0 | V9: =IF(D9="End of range","END OF RANGE",IF(T9="","NO BUFFER SET",IF(H9<=0,IF(O9<T9,"OUT - REORDER","OUT - ON ORDER"),IF(O9<T9,"REORDER",IF(H9<T9,"LOW - ON ORDER",IF(AND(S9<>"",N(S9)>Settings!$B$5),"SLOW MOVER","OK")))))) -> OK | X9: =IF(OR(D9="End of range",U9=""),0,IF(N(U9)>0,U9+ROW()/1000000,0)) -> 0
A10: GAZ008 | B10: GAZELLE WHITE | C10: Hide | D10: Active | E10: =SUMIFS('CPT Count'!$D:$D,'CPT Count'!$A:$A,$A10)-SUMIFS('Weekly Sales'!$F:$F,'Weekly Sales'!$H:$H,$A10,'Weekly Sales'!$I:$I,"CPT")+SUMIFS(Transfers!$F:$F,Transfers!$C:$C,$A10,Transfers!$J:$J,"CPT")-SUMIFS(Transfers!$F:$F,Transfers!$C:$C,$A10,Transfers!$I:$I,"CPT",Transfers!$H:$H,"<>Y")+SUMIFS('Stock Received'!$I:$I,'Stock Received'!$E:$E,$A10,'Stock Received'!$L:$L,"CPT") -> 740 | F10: =SUMIFS('JHB Count'!$E:$E,'JHB Count'!$F:$F,$A10)-SUMIFS('Weekly Sales'!$F:$F,'Weekly Sales'!$H:$H,$A10,'Weekly Sales'!$I:$I,"JHB")+SUMIFS(Transfers!$F:$F,Transfers!$C:$C,$A10,Transfers!$J:$J,"JHB")-SUMIFS(Transfers!$F:$F,Transfers!$C:$C,$A10,Transfers!$I:$I,"JHB",Transfers!$H:$H,"<>Y")+SUMIFS('Stock Received'!$I:$I,'Stock Received'!$E:$E,$A10,'Stock Received'!$L:$L,"JHB") -> 56 | G10: =SUMIFS('DBN Count'!$D:$D,'DBN Count'!$E:$E,$A10)-SUMIFS('Weekly Sales'!$F:$F,'Weekly Sales'!$H:$H,$A10,'Weekly Sales'!$I:$I,"DBN")+SUMIFS(Transfers!$F:$F,Transfers!$C:$C,$A10,Transfers!$J:$J,"DBN")-SUMIFS(Transfers!$F:$F,Transfers!$C:$C,$A10,Transfers!$I:$I,"DBN",Transfers!$H:$H,"<>Y")+SUMIFS('Stock Received'!$I:$I,'Stock Received'!$E:$E,$A10,'Stock Received'!$L:$L,"DBN") -> 58.96 | H10: =E10+F10+G10 -> 854.96 | I10: =SUMIFS('Weekly Sales'!$F:$F,'Weekly Sales'!$H:$H,$A10) -> 0 | J10: =SUMIFS(Orders!$L:$L,Orders!$D:$D,$A10,Orders!$F:$F,">="&J$4,Orders!$F:$F,"<"&EDATE(J$4,1)) -> 0 | K10: =SUMIFS(Orders!$L:$L,Orders!$D:$D,$A10,Orders!$F:$F,">="&K$4,Orders!$F:$F,"<"&EDATE(K$4,1)) -> 0 | L10: =SUMIFS(Orders!$L:$L,Orders!$D:$D,$A10,Orders!$F:$F,">="&L$4,Orders!$F:$F,"<"&EDATE(L$4,1)) -> 0 | M10: =N10-J10-K10-L10 -> 0 | N10: =SUMIFS(Orders!$L:$L,Orders!$D:$D,$A10) -> 0 | O10: =H10+N10 -> 854.96 | P10: 100 | Q10: =IF(SUMIFS('Sales History'!$E:$E,'Sales History'!$G:$G,$A10)>0,SUMIFS('Sales History'!$E:$E,'Sales History'!$G:$G,$A10)/Settings!$B$4,N(P10)) -> 100 | R10: =IF(SUMIFS('Sales History'!$E:$E,'Sales History'!$G:$G,$A10)>0,"6-month history",IF(N(P10)>0,"Current sheet","No sales data")) -> Current sheet | S10: =IF(Q10>0,H10/Q10,"") -> 8.5496 | T10: 300 | U10: =IF(T10="","",MAX(0,T10-O10)) -> 0 | V10: =IF(D10="End of range","END OF RANGE",IF(T10="","NO BUFFER SET",IF(H10<=0,IF(O10<T10,"OUT - REORDER","OUT - ON ORDER"),IF(O10<T10,"REORDER",IF(H10<T10,"LOW - ON ORDER",IF(AND(S10<>"",N(S10)>Settings!$B$5),"SLOW MOVER","OK")))))) -> OK | X10: =IF(OR(D10="End of range",U10=""),0,IF(N(U10)>0,U10+ROW()/1000000,0)) -> 0
A11: GAZ015 | B11: GAZELLE OYSTER | C11: Hide | D11: Active | E11: =SUMIFS('CPT Count'!$D:$D,'CPT Count'!$A:$A,$A11)-SUMIFS('Weekly Sales'!$F:$F,'Weekly Sales'!$H:$H,$A11,'Weekly Sales'!$I:$I,"CPT")+SUMIFS(Transfers!$F:$F,Transfers!$C:$C,$A11,Transfers!$J:$J,"CPT")-SUMIFS(Transfers!$F:$F,Transfers!$C:$C,$A11,Transfers!$I:$I,"CPT",Transfers!$H:$H,"<>Y")+SUMIFS('Stock Received'!$I:$I,'Stock Received'!$E:$E,$A11,'Stock Received'!$L:$L,"CPT") -> 160.06 | F11: =SUMIFS('JHB Count'!$E:$E,'JHB Count'!$F:$F,$A11)-SUMIFS('Weekly Sales'!$F:$F,'Weekly Sales'!$H:$H,$A11,'Weekly Sales'!$I:$I,"JHB")+SUMIFS(Transfers!$F:$F,Transfers!$C:$C,$A11,Transfers!$J:$J,"JHB")-SUMIFS(Transfers!$F:$F,Transfers!$C:$C,$A11,Transfers!$I:$I,"JHB",Transfers!$H:$H,"<>Y")+SUMIFS('Stock Received'!$I:$I,'Stock Received'!$E:$E,$A11,'Stock Received'!$L:$L,"JHB") -> 87.18 | G11: =SUMIFS('DBN Count'!$D:$D,'DBN Count'!$E:$E,$A11)-SUMIFS('Weekly Sales'!$F:$F,'Weekly Sales'!$H:$H,$A11,'Weekly Sales'!$I:$I,"DBN")+SUMIFS(Transfers!$F:$F,Transfers!$C:$C,$A11,Transfers!$J:$J,"DBN")-SUMIFS(Transfers!$F:$F,Transfers!$C:$C,$A11,Transfers!$I:$I,"DBN",Transfers!$H:$H,"<>Y")+SUMIFS('Stock Received'!$I:$I,'Stock Received'!$E:$E,$A11,'Stock Received'!$L:$L,"DBN") -> 49.17 | H11: =E11+F11+G11 -> 296.41 | I11: =SUMIFS('Weekly Sales'!$F:$F,'Weekly Sales'!$H:$H,$A11) -> 64.76 | J11: =SUMIFS(Orders!$L:$L,Orders!$D:$D,$A11,Orders!$F:$F,">="&J$4,Orders!$F:$F,"<"&EDATE(J$4,1)) -> 0 | K11: =SUMIFS(Orders!$L:$L,Orders!$D:$D,$A11,Orders!$F:$F,">="&K$4,Orders!$F:$F,"<"&EDATE(K$4,1)) -> 500 | L11: =SUMIFS(Orders!$L:$L,Orders!$D:$D,$A11,Orders!$F:$F,">="&L$4,Orders!$F:$F,"<"&EDATE(L$4,1)) -> 0 | M11: =N11-J11-K11-L11 -> 0 | N11: =SUMIFS(Orders!$L:$L,Orders!$D:$D,$A11) -> 500 | O11: =H11+N11 -> 796.41 | P11: 210 | Q11: =IF(SUMIFS('Sales History'!$E:$E,'Sales History'!$G:$G,$A11)>0,SUMIFS('Sales History'!$E:$E,'Sales History'!$G:$G,$A11)/Settings!$B$4,N(P11)) -> 210 | R11: =IF(SUMIFS('Sales History'!$E:$E,'Sales History'!$G:$G,$A11)>0,"6-month history",IF(N(P11)>0,"Current sheet","No sales data")) -> Current sheet | S11: =IF(Q11>0,H11/Q11,"") -> 1.4114762 | T11: 300 | U11: =IF(T11="","",MAX(0,T11-O11)) -> 0 | V11: =IF(D11="End of range","END OF RANGE",IF(T11="","NO BUFFER SET",IF(H11<=0,IF(O11<T11,"OUT - REORDER","OUT - ON ORDER"),IF(O11<T11,"REORDER",IF(H11<T11,"LOW - ON ORDER",IF(AND(S11<>"",N(S11)>Settings!$B$5),"SLOW MOVER","OK")))))) -> LOW - ON ORDER | X11: =IF(OR(D11="End of range",U11=""),0,IF(N(U11)>0,U11+ROW()/1000000,0)) -> 0
A12: GAZ012 | B12: GAZELLE GREY | C12: Hide | D12: Active | E12: =SUMIFS('CPT Count'!$D:$D,'CPT Count'!$A:$A,$A12)-SUMIFS('Weekly Sales'!$F:$F,'Weekly Sales'!$H:$H,$A12,'Weekly Sales'!$I:$I,"CPT")+SUMIFS(Transfers!$F:$F,Transfers!$C:$C,$A12,Transfers!$J:$J,"CPT")-SUMIFS(Transfers!$F:$F,Transfers!$C:$C,$A12,Transfers!$I:$I,"CPT",Transfers!$H:$H,"<>Y")+SUMIFS('Stock Received'!$I:$I,'Stock Received'!$E:$E,$A12,'Stock Received'!$L:$L,"CPT") -> 288 | F12: =SUMIFS('JHB Count'!$E:$E,'JHB Count'!$F:$F,$A12)-SUMIFS('Weekly Sales'!$F:$F,'Weekly Sales'!$H:$H,$A12,'Weekly Sales'!$I:$I,"JHB")+SUMIFS(Transfers!$F:$F,Transfers!$C:$C,$A12,Transfers!$J:$J,"JHB")-SUMIFS(Transfers!$F:$F,Transfers!$C:$C,$A12,Transfers!$I:$I,"JHB",Transfers!$H:$H,"<>Y")+SUMIFS('Stock Received'!$I:$I,'Stock Received'!$E:$E,$A12,'Stock Received'!$L:$L,"JHB") -> 92 | G12: =SUMIFS('DBN Count'!$D:$D,'DBN Count'!$E:$E,$A12)-SUMIFS('Weekly Sales'!$F:$F,'Weekly Sales'!$H:$H,$A12,'Weekly Sales'!$I:$I,"DBN")+SUMIFS(Transfers!$F:$F,Transfers!$C:$C,$A12,Transfers!$J:$J,"DBN")-SUMIFS(Transfers!$F:$F,Transfers!$C:$C,$A12,Transfers!$I:$I,"DBN",Transfers!$H:$H,"<>Y")+SUMIFS('Stock Received'!$I:$I,'Stock Received'!$E:$E,$A12,'Stock Received'!$L:$L,"DBN") -> 81.3 | H12: =E12+F12+G12 -> 461.3 | I12: =SUMIFS('Weekly Sales'!$F:$F,'Weekly Sales'!$H:$H,$A12) -> 0 | J12: =SUMIFS(Orders!$L:$L,Orders!$D:$D,$A12,Orders!$F:$F,">="&J$4,Orders!$F:$F,"<"&EDATE(J$4,1)) -> 0 | K12: =SUMIFS(Orders!$L:$L,Orders!$D:$D,$A12,Orders!$F:$F,">="&K$4,Orders!$F:$F,"<"&EDATE(K$4,1)) -> 0 | L12: =SUMIFS(Orders!$L:$L,Orders!$D:$D,$A12,Orders!$F:$F,">="&L$4,Orders!$F:$F,"<"&EDATE(L$4,1)) -> 0 | M12: =N12-J12-K12-L12 -> 0 | N12: =SUMIFS(Orders!$L:$L,Orders!$D:$D,$A12) -> 0 | O12: =H12+N12 -> 461.3 | P12: 35 | Q12: =IF(SUMIFS('Sales History'!$E:$E,'Sales History'!$G:$G,$A12)>0,SUMIFS('Sales History'!$E:$E,'Sales History'!$G:$G,$A12)/Settings!$B$4,N(P12)) -> 35 | R12: =IF(SUMIFS('Sales History'!$E:$E,'Sales History'!$G:$G,$A12)>0,"6-month history",IF(N(P12)>0,"Current sheet","No sales data")) -> Current sheet | S12: =IF(Q12>0,H12/Q12,"") -> 13.18 | T12: 200 | U12: =IF(T12="","",MAX(0,T12-O12)) -> 0 | V12: =IF(D12="End of range","END OF RANGE",IF(T12="","NO BUFFER SET",IF(H12<=0,IF(O12<T12,"OUT - REORDER","OUT - ON ORDER"),IF(O12<T12,"REORDER",IF(H12<T12,"LOW - ON ORDER",IF(AND(S12<>"",N(S12)>Settings!$B$5),"SLOW MOVER","OK")))))) -> SLOW MOVER | X12: =IF(OR(D12="End of range",U12=""),0,IF(N(U12)>0,U12+ROW()/1000000,0)) -> 0
A13: PRE001 | B13: GAZELLE LATTE | C13: Hide | D13: Active | E13: =SUMIFS('CPT Count'!$D:$D,'CPT Count'!$A:$A,$A13)-SUMIFS('Weekly Sales'!$F:$F,'Weekly Sales'!$H:$H,$A13,'Weekly Sales'!$I:$I,"CPT")+SUMIFS(Transfers!$F:$F,Transfers!$C:$C,$A13,Transfers!$J:$J,"CPT")-SUMIFS(Transfers!$F:$F,Transfers!$C:$C,$A13,Transfers!$I:$I,"CPT",Transfers!$H:$H,"<>Y")+SUMIFS('Stock Received'!$I:$I,'Stock Received'!$E:$E,$A13,'Stock Received'!$L:$L,"CPT") -> 1452.11 | F13: =SUMIFS('JHB Count'!$E:$E,'JHB Count'!$F:$F,$A13)-SUMIFS('Weekly Sales'!$F:$F,'Weekly Sales'!$H:$H,$A13,'Weekly Sales'!$I:$I,"JHB")+SUMIFS(Transfers!$F:$F,Transfers!$C:$C,$A13,Transfers!$J:$J,"JHB")-SUMIFS(Transfers!$F:$F,Transfers!$C:$C,$A13,Transfers!$I:$I,"JHB",Transfers!$H:$H,"<>Y")+SUMIFS('Stock Received'!$I:$I,'Stock Received'!$E:$E,$A13,'Stock Received'!$L:$L,"JHB") -> 95.8 | G13: =SUMIFS('DBN Count'!$D:$D,'DBN Count'!$E:$E,$A13)-SUMIFS('Weekly Sales'!$F:$F,'Weekly Sales'!$H:$H,$A13,'Weekly Sales'!$I:$I,"DBN")+SUMIFS(Transfers!$F:$F,Transfers!$C:$C,$A13,Transfers!$J:$J,"DBN")-SUMIFS(Transfers!$F:$F,Transfers!$C:$C,$A13,Transfers!$I:$I,"DBN",Transfers!$H:$H,"<>Y")+SUMIFS('Stock Received'!$I:$I,'Stock Received'!$E:$E,$A13,'Stock Received'!$L:$L,"DBN") -> 48.45 | H13: =E13+F13+G13 -> 1596.36 | I13: =SUMIFS('Weekly Sales'!$F:$F,'Weekly Sales'!$H:$H,$A13) -> 36.09 | J13: =SUMIFS(Orders!$L:$L,Orders!$D:$D,$A13,Orders!$F:$F,">="&J$4,Orders!$F:$F,"<"&EDATE(J$4,1)) -> 0 | K13: =SUMIFS(Orders!$L:$L,Orders!$D:$D,$A13,Orders!$F:$F,">="&K$4,Orders!$F:$F,"<"&EDATE(K$4,1)) -> 0 | L13: =SUMIFS(Orders!$L:$L,Orders!$D:$D,$A13,Orders!$F:$F,">="&L$4,Orders!$F:$F,"<"&EDATE(L$4,1)) -> 0 | M13: =N13-J13-K13-L13 -> 0 | N13: =SUMIFS(Orders!$L:$L,Orders!$D:$D,$A13) -> 0 | O13: =H13+N13 -> 1596.36 | P13: 175 | Q13: =IF(SUMIFS('Sales History'!$E:$E,'Sales History'!$G:$G,$A13)>0,SUMIFS('Sales History'!$E:$E,'Sales History'!$G:$G,$A13)/Settings!$B$4,N(P13)) -> 175 | R13: =IF(SUMIFS('Sales History'!$E:$E,'Sales History'!$G:$G,$A13)>0,"6-month history",IF(N(P13)>0,"Current sheet","No sales data")) -> Current sheet | S13: =IF(Q13>0,H13/Q13,"") -> 9.1220571 | T13: 300 | U13: =IF(T13="","",MAX(0,T13-O13)) -> 0 | V13: =IF(D13="End of range","END OF RANGE",IF(T13="","NO BUFFER SET",IF(H13<=0,IF(O13<T13,"OUT - REORDER","OUT - ON ORDER"),IF(O13<T13,"REORDER",IF(H13<T13,"LOW - ON ORDER",IF(AND(S13<>"",N(S13)>Settings!$B$5),"SLOW MOVER","OK")))))) -> OK | X13: =IF(OR(D13="End of range",U13=""),0,IF(N(U13)>0,U13+ROW()/1000000,0)) -> 0
A14: NAP010 | B14: BALLET NAPPA NUDE (HAN) | C14: Hide | D14: Active | E14: =SUMIFS('CPT Count'!$D:$D,'CPT Count'!$A:$A,$A14)-SUMIFS('Weekly Sales'!$F:$F,'Weekly Sales'!$H:$H,$A14,'Weekly Sales'!$I:$I,"CPT")+SUMIFS(Transfers!$F:$F,Transfers!$C:$C,$A14,Transfers!$J:$J,"CPT")-SUMIFS(Transfers!$F:$F,Transfers!$C:$C,$A14,Transfers!$I:$I,"CPT",Transfers!$H:$H,"<>Y")+SUMIFS('Stock Received'!$I:$I,'Stock Received'!$E:$E,$A14,'Stock Received'!$L:$L,"CPT") -> 275.88 | F14: =SUMIFS('JHB Count'!$E:$E,'JHB Count'!$F:$F,$A14)-SUMIFS('Weekly Sales'!$F:$F,'Weekly Sales'!$H:$H,$A14,'Weekly Sales'!$I:$I,"JHB")+SUMIFS(Transfers!$F:$F,Transfers!$C:$C,$A14,Transfers!$J:$J,"JHB")-SUMIFS(Transfers!$F:$F,Transfers!$C:$C,$A14,Transfers!$I:$I,"JHB",Transfers!$H:$H,"<>Y")+SUMIFS('Stock Received'!$I:$I,'Stock Received'!$E:$E,$A14,'Stock Received'!$L:$L,"JHB") -> 0 | G14: =SUMIFS('DBN Count'!$D:$D,'DBN Count'!$E:$E,$A14)-SUMIFS('Weekly Sales'!$F:$F,'Weekly Sales'!$H:$H,$A14,'Weekly Sales'!$I:$I,"DBN")+SUMIFS(Transfers!$F:$F,Transfers!$C:$C,$A14,Transfers!$J:$J,"DBN")-SUMIFS(Transfers!$F:$F,Transfers!$C:$C,$A14,Transfers!$I:$I,"DBN",Transfers!$H:$H,"<>Y")+SUMIFS('Stock Received'!$I:$I,'Stock Received'!$E:$E,$A14,'Stock Received'!$L:$L,"DBN") -> 2.13 | H14: =E14+F14+G14 -> 278.01 | I14: =SUMIFS('Weekly Sales'!$F:$F,'Weekly Sales'!$H:$H,$A14) -> 4.12 | J14: =SUMIFS(Orders!$L:$L,Orders!$D:$D,$A14,Orders!$F:$F,">="&J$4,Orders!$F:$F,"<"&EDATE(J$4,1)) -> 0 | K14: =SUMIFS(Orders!$L:$L,Orders!$D:$D,$A14,Orders!$F:$F,">="&K$4,Orders!$F:$F,"<"&EDATE(K$4,1)) -> 0 | L14: =SUMIFS(Orders!$L:$L,Orders!$D:$D,$A14,Orders!$F:$F,">="&L$4,Orders!$F:$F,"<"&EDATE(L$4,1)) -> 0 | M14: =N14-J14-K14-L14 -> 0 | N14: =SUMIFS(Orders!$L:$L,Orders!$D:$D,$A14) -> 0 | O14: =H14+N14 -> 278.01 | P14: 50 | Q14: =IF(SUMIFS('Sales History'!$E:$E,'Sales History'!$G:$G,$A14)>0,SUMIFS('Sales History'!$E:$E,'Sales History'!$G:$G,$A14)/Settings!$B$4,N(P14)) -> 50 | R14: =IF(SUMIFS('Sales History'!$E:$E,'Sales History'!$G:$G,$A14)>0,"6-month history",IF(N(P14)>0,"Current sheet","No sales data")) -> Current sheet | S14: =IF(Q14>0,H14/Q14,"") -> 5.5602 | T14: 200 | U14: =IF(T14="","",MAX(0,T14-O14)) -> 0 | V14: =IF(D14="End of range","END OF RANGE",IF(T14="","NO BUFFER SET",IF(H14<=0,IF(O14<T14,"OUT - REORDER","OUT - ON ORDER"),IF(O14<T14,"REORDER",IF(H14<T14,"LOW - ON ORDER",IF(AND(S14<>"",N(S14)>Settings!$B$5),"SLOW MOVER","OK")))))) -> OK | X14: =IF(OR(D14="End of range",U14=""),0,IF(N(U14)>0,U14+ROW()/1000000,0)) -> 0
A15: MOR004 | B15: MOROCCO STRAW | C15: Hide | D15: Active | E15: =SUMIFS('CPT Count'!$D:$D,'CPT Count'!$A:$A,$A15)-SUMIFS('Weekly Sales'!$F:$F,'Weekly Sales'!$H:$H,$A15,'Weekly Sales'!$I:$I,"CPT")+SUMIFS(Transfers!$F:$F,Transfers!$C:$C,$A15,Transfers!$J:$J,"CPT")-SUMIFS(Transfers!$F:$F,Transfers!$C:$C,$A15,Transfers!$I:$I,"CPT",Transfers!$H:$H,"<>Y")+SUMIFS('Stock Received'!$I:$I,'Stock Received'!$E:$E,$A15,'Stock Received'!$L:$L,"CPT") -> 598.42 | F15: =SUMIFS('JHB Count'!$E:$E,'JHB Count'!$F:$F,$A15)-SUMIFS('Weekly Sales'!$F:$F,'Weekly Sales'!$H:$H,$A15,'Weekly Sales'!$I:$I,"JHB")+SUMIFS(Transfers!$F:$F,Transfers!$C:$C,$A15,Transfers!$J:$J,"JHB")-SUMIFS(Transfers!$F:$F,Transfers!$C:$C,$A15,Transfers!$I:$I,"JHB",Transfers!$H:$H,"<>Y")+SUMIFS('Stock Received'!$I:$I,'Stock Received'!$E:$E,$A15,'Stock Received'!$L:$L,"JHB") -> 39.88 | G15: =SUMIFS('DBN Count'!$D:$D,'DBN Count'!$E:$E,$A15)-SUMIFS('Weekly Sales'!$F:$F,'Weekly Sales'!$H:$H,$A15,'Weekly Sales'!$I:$I,"DBN")+SUMIFS(Transfers!$F:$F,Transfers!$C:$C,$A15,Transfers!$J:$J,"DBN")-SUMIFS(Transfers!$F:$F,Transfers!$C:$C,$A15,Transfers!$I:$I,"DBN",Transfers!$H:$H,"<>Y")+SUMIFS('Stock Received'!$I:$I,'Stock Received'!$E:$E,$A15,'Stock Received'!$L:$L,"DBN") -> 15.56 | H15: =E15+F15+G15 -> 653.86 | I15: =SUMIFS('Weekly Sales'!$F:$F,'Weekly Sales'!$H:$H,$A15) -> 25.33 | J15: =SUMIFS(Orders!$L:$L,Orders!$D:$D,$A15,Orders!$F:$F,">="&J$4,Orders!$F:$F,"<"&EDATE(J$4,1)) -> 0 | K15: =SUMIFS(Orders!$L:$L,Orders!$D:$D,$A15,Orders!$F:$F,">="&K$4,Orders!$F:$F,"<"&EDATE(K$4,1)) -> 0 | L15: =SUMIFS(Orders!$L:$L,Orders!$D:$D,$A15,Orders!$F:$F,">="&L$4,Orders!$F:$F,"<"&EDATE(L$4,1)) -> 300 | M15: =N15-J15-K15-L15 -> 0 | N15: =SUMIFS(Orders!$L:$L,Orders!$D:$D,$A15) -> 300 | O15: =H15+N15 -> 953.86 | P15: 200 | Q15: =IF(SUMIFS('Sales History'!$E:$E,'Sales History'!$G:$G,$A15)>0,SUMIFS('Sales History'!$E:$E,'Sales History'!$G:$G,$A15)/Settings!$B$4,N(P15)) -> 200 | R15: =IF(SUMIFS('Sales History'!$E:$E,'Sales History'!$G:$G,$A15)>0,"6-month history",IF(N(P15)>0,"Current sheet","No sales data")) -> Current sheet | S15: =IF(Q15>0,H15/Q15,"") -> 3.2693 | T15: 300 | U15: =IF(T15="","",MAX(0,T15-O15)) -> 0 | V15: =IF(D15="End of range","END OF RANGE",IF(T15="","NO BUFFER SET",IF(H15<=0,IF(O15<T15,"OUT - REORDER","OUT - ON ORDER"),IF(O15<T15,"REORDER",IF(H15<T15,"LOW - ON ORDER",IF(AND(S15<>"",N(S15)>Settings!$B$5),"SLOW MOVER","OK")))))) -> OK | X15: =IF(OR(D15="End of range",U15=""),0,IF(N(U15)>0,U15+ROW()/1000000,0)) -> 0
A16: MOR003 | B16: MOROCCO CHOCOLATE | C16: Hide | D16: Active | E16: =SUMIFS('CPT Count'!$D:$D,'CPT Count'!$A:$A,$A16)-SUMIFS('Weekly Sales'!$F:$F,'Weekly Sales'!$H:$H,$A16,'Weekly Sales'!$I:$I,"CPT")+SUMIFS(Transfers!$F:$F,Transfers!$C:$C,$A16,Transfers!$J:$J,"CPT")-SUMIFS(Transfers!$F:$F,Transfers!$C:$C,$A16,Transfers!$I:$I,"CPT",Transfers!$H:$H,"<>Y")+SUMIFS('Stock Received'!$I:$I,'Stock Received'!$E:$E,$A16,'Stock Received'!$L:$L,"CPT") -> 309 | F16: =SUMIFS('JHB Count'!$E:$E,'JHB Count'!$F:$F,$A16)-SUMIFS('Weekly Sales'!$F:$F,'Weekly Sales'!$H:$H,$A16,'Weekly Sales'!$I:$I,"JHB")+SUMIFS(Transfers!$F:$F,Transfers!$C:$C,$A16,Transfers!$J:$J,"JHB")-SUMIFS(Transfers!$F:$F,Transfers!$C:$C,$A16,Transfers!$I:$I,"JHB",Transfers!$H:$H,"<>Y")+SUMIFS('Stock Received'!$I:$I,'Stock Received'!$E:$E,$A16,'Stock Received'!$L:$L,"JHB") -> 64.33 | G16: =SUMIFS('DBN Count'!$D:$D,'DBN Count'!$E:$E,$A16)-SUMIFS('Weekly Sales'!$F:$F,'Weekly Sales'!$H:$H,$A16,'Weekly Sales'!$I:$I,"DBN")+SUMIFS(Transfers!$F:$F,Transfers!$C:$C,$A16,Transfers!$J:$J,"DBN")-SUMIFS(Transfers!$F:$F,Transfers!$C:$C,$A16,Transfers!$I:$I,"DBN",Transfers!$H:$H,"<>Y")+SUMIFS('Stock Received'!$I:$I,'Stock Received'!$E:$E,$A16,'Stock Received'!$L:$L,"DBN") -> 23.9 | H16: =E16+F16+G16 -> 397.23 | I16: =SUMIFS('Weekly Sales'!$F:$F,'Weekly Sales'!$H:$H,$A16) -> 3.67 | J16: =SUMIFS(Orders!$L:$L,Orders!$D:$D,$A16,Orders!$F:$F,">="&J$4,Orders!$F:$F,"<"&EDATE(J$4,1)) -> 0 | K16: =SUMIFS(Orders!$L:$L,Orders!$D:$D,$A16,Orders!$F:$F,">="&K$4,Orders!$F:$F,"<"&EDATE(K$4,1)) -> 300 | L16: =SUMIFS(Orders!$L:$L,Orders!$D:$D,$A16,Orders!$F:$F,">="&L$4,Orders!$F:$F,"<"&EDATE(L$4,1)) -> 300 | M16: =N16-J16-K16-L16 -> 0 | N16: =SUMIFS(Orders!$L:$L,Orders!$D:$D,$A16) -> 600 | O16: =H16+N16 -> 997.23 | P16: 85 | Q16: =IF(SUMIFS('Sales History'!$E:$E,'Sales History'!$G:$G,$A16)>0,SUMIFS('Sales History'!$E:$E,'Sales History'!$G:$G,$A16)/Settings!$B$4,N(P16)) -> 85 | R16: =IF(SUMIFS('Sales History'!$E:$E,'Sales History'!$G:$G,$A16)>0,"6-month history",IF(N(P16)>0,"Current sheet","No sales data")) -> Current sheet | S16: =IF(Q16>0,H16/Q16,"") -> 4.6732941 | T16: 300 | U16: =IF(T16="","",MAX(0,T16-O16)) -> 0 | V16: =IF(D16="End of range","END OF RANGE",IF(T16="","NO BUFFER SET",IF(H16<=0,IF(O16<T16,"OUT - REORDER","OUT - ON ORDER"),IF(O16<T16,"REORDER",IF(H16<T16,"LOW - ON ORDER",IF(AND(S16<>"",N(S16)>Settings!$B$5),"SLOW MOVER","OK")))))) -> OK | X16: =IF(OR(D16="End of range",U16=""),0,IF(N(U16)>0,U16+ROW()/1000000,0)) -> 0
... A18: MOR010 | B18: MOROCCO RUBY | C18: Hide | D18: Active | E18: =SUMIFS('CPT Count'!$D:$D,'CPT Count'!$A:$A,$A18)-SUMIFS('Weekly Sales'!$F:$F,'Weekly Sales'!$H:$H,$A18,'Weekly Sales'!$I:$I,"CPT")+SUMIFS(Transfers!$F:$F,Transfers!$C:$C,$A18,Transfers!$J:$J,"CPT")-SUMIFS(Transfers!$F:$F,Transfers!$C:$C,$A18,Transfers!$I:$I,"CPT",Transfers!$H:$H,"<>Y")+SUMIFS('Stock Received'!$I:$I,'Stock Received'!$E:$E,$A18,'Stock Received'!$L:$L,"CPT") -> 406.37 | F18: =SUMIFS('JHB Count'!$E:$E,'JHB Count'!$F:$F,$A18)-SUMIFS('Weekly Sales'!$F:$F,'Weekly Sales'!$H:$H,$A18,'Weekly Sales'!$I:$I,"JHB")+SUMIFS(Transfers!$F:$F,Transfers!$C:$C,$A18,Transfers!$J:$J,"JHB")-SUMIFS(Transfers!$F:$F,Transfers!$C:$C,$A18,Transfers!$I:$I,"JHB",Transfers!$H:$H,"<>Y")+SUMIFS('Stock Received'!$I:$I,'Stock Received'!$E:$E,$A18,'Stock Received'!$L:$L,"JHB") -> 24.86 | G18: =SUMIFS('DBN Count'!$D:$D,'DBN Count'!$E:$E,$A18)-SUMIFS('Weekly Sales'!$F:$F,'Weekly Sales'!$H:$H,$A18,'Weekly Sales'!$I:$I,"DBN")+SUMIFS(Transfers!$F:$F,Transfers!$C:$C,$A18,Transfers!$J:$J,"DBN")-SUMIFS(Transfers!$F:$F,Transfers!$C:$C,$A18,Transfers!$I:$I,"DBN",Transfers!$H:$H,"<>Y")+SUMIFS('Stock Received'!$I:$I,'Stock Received'!$E:$E,$A18,'Stock Received'!$L:$L,"DBN") -> 24.23 | H18: =E18+F18+G18 -> 455.46 | I18: =SUMIFS('Weekly Sales'!$F:$F,'Weekly Sales'!$H:$H,$A18) -> 69.36 | J18: =SUMIFS(Orders!$L:$L,Orders!$D:$D,$A18,Orders!$F:$F,">="&J$4,Orders!$F:$F,"<"&EDATE(J$4,1)) -> 0 | K18: =SUMIFS(Orders!$L:$L,Orders!$D:$D,$A18,Orders!$F:$F,">="&K$4,Orders!$F:$F,"<"&EDATE(K$4,1)) -> 300 | L18: =SUMIFS(Orders!$L:$L,Orders!$D:$D,$A18,Orders!$F:$F,">="&L$4,Orders!$F:$F,"<"&EDATE(L$4,1)) -> 0 | M18: =N18-J18-K18-L18 -> 0 | N18: =SUMIFS(Orders!$L:$L,Orders!$D:$D,$A18) -> 300 | O18: =H18+N18 -> 755.46 | P18: 200 | Q18: =IF(SUMIFS('Sales History'!$E:$E,'Sales History'!$G:$G,$A18)>0,SUMIFS('Sales History'!$E:$E,'Sales History'!$G:$G,$A18)/Settings!$B$4,N(P18)) -> 200 | R18: =IF(SUMIFS('Sales History'!$E:$E,'Sales History'!$G:$G,$A18)>0,"6-month history",IF(N(P18)>0,"Current sheet","No sales data")) -> Current sheet | S18: =IF(Q18>0,H18/Q18,"") -> 2.2773 | T18: 300 | U18: =IF(T18="","",MAX(0,T18-O18)) -> 0 | V18: =IF(D18="End of range","END OF RANGE",IF(T18="","NO BUFFER SET",IF(H18<=0,IF(O18<T18,"OUT - REORDER","OUT - ON ORDER"),IF(O18<T18,"REORDER",IF(H18<T18,"LOW - ON ORDER",IF(AND(S18<>"",N(S18)>Settings!$B$5),"SLOW MOVER","OK")))))) -> OK | X18: =IF(OR(D18="End of range",U18=""),0,IF(N(U18)>0,U18+ROW()/1000000,0)) -> 0
A19: SOR001 | B19: SORRENTO BLACK | C19: Hide | D19: Active | E19: =SUMIFS('CPT Count'!$D:$D,'CPT Count'!$A:$A,$A19)-SUMIFS('Weekly Sales'!$F:$F,'Weekly Sales'!$H:$H,$A19,'Weekly Sales'!$I:$I,"CPT")+SUMIFS(Transfers!$F:$F,Transfers!$C:$C,$A19,Transfers!$J:$J,"CPT")-SUMIFS(Transfers!$F:$F,Transfers!$C:$C,$A19,Transfers!$I:$I,"CPT",Transfers!$H:$H,"<>Y")+SUMIFS('Stock Received'!$I:$I,'Stock Received'!$E:$E,$A19,'Stock Received'!$L:$L,"CPT") -> 0 | F19: =SUMIFS('JHB Count'!$E:$E,'JHB Count'!$F:$F,$A19)-SUMIFS('Weekly Sales'!$F:$F,'Weekly Sales'!$H:$H,$A19,'Weekly Sales'!$I:$I,"JHB")+SUMIFS(Transfers!$F:$F,Transfers!$C:$C,$A19,Transfers!$J:$J,"JHB")-SUMIFS(Transfers!$F:$F,Transfers!$C:$C,$A19,Transfers!$I:$I,"JHB",Transfers!$H:$H,"<>Y")+SUMIFS('Stock Received'!$I:$I,'Stock Received'!$E:$E,$A19,'Stock Received'!$L:$L,"JHB") -> 1265.16 | G19: =SUMIFS('DBN Count'!$D:$D,'DBN Count'!$E:$E,$A19)-SUMIFS('Weekly Sales'!$F:$F,'Weekly Sales'!$H:$H,$A19,'Weekly Sales'!$I:$I,"DBN")+SUMIFS(Transfers!$F:$F,Transfers!$C:$C,$A19,Transfers!$J:$J,"DBN")-SUMIFS(Transfers!$F:$F,Transfers!$C:$C,$A19,Transfers!$I:$I,"DBN",Transfers!$H:$H,"<>Y")+SUMIFS('Stock Received'!$I:$I,'Stock Received'!$E:$E,$A19,'Stock Received'!$L:$L,"DBN") -> 109.15 | H19: =E19+F19+G19 -> 1374.31 | I19: =SUMIFS('Weekly Sales'!$F:$F,'Weekly Sales'!$H:$H,$A19) -> 126.84 | J19: =SUMIFS(Orders!$L:$L,Orders!$D:$D,$A19,Orders!$F:$F,">="&J$4,Orders!$F:$F,"<"&EDATE(J$4,1)) -> 0 | K19: =SUMIFS(Orders!$L:$L,Orders!$D:$D,$A19,Orders!$F:$F,">="&K$4,Orders!$F:$F,"<"&EDATE(K$4,1)) -> 1000 | L19: =SUMIFS(Orders!$L:$L,Orders!$D:$D,$A19,Orders!$F:$F,">="&L$4,Orders!$F:$F,"<"&EDATE(L$4,1)) -> 0 | M19: =N19-J19-K19-L19 -> 0 | N19: =SUMIFS(Orders!$L:$L,Orders!$D:$D,$A19) -> 1000 | O19: =H19+N19 -> 2374.31 | P19: 0 | Q19: =IF(SUMIFS('Sales History'!$E:$E,'Sales History'!$G:$G,$A19)>0,SUMIFS('Sales History'!$E:$E,'Sales History'!$G:$G,$A19)/Settings!$B$4,N(P19)) -> 0 | R19: =IF(SUMIFS('Sales History'!$E:$E,'Sales History'!$G:$G,$A19)>0,"6-month history",IF(N(P19)>0,"Current sheet","No sales data")) -> No sales data | S19: =IF(Q19>0,H19/Q19,"") | U19: =IF(T19="","",MAX(0,T19-O19)) | V19: =IF(D19="End of range","END OF RANGE",IF(T19="","NO BUFFER SET",IF(H19<=0,IF(O19<T19,"OUT - REORDER","OUT - ON ORDER"),IF(O19<T19,"REORDER",IF(H19<T19,"LOW - ON ORDER",IF(AND(S19<>"",N(S19)>Settings!$B$5),"SLOW MOVER","OK")))))) -> NO BUFFER SET | X19: =IF(OR(D19="End of range",U19=""),0,IF(N(U19)>0,U19+ROW()/1000000,0)) -> 0
A20: SOR012 | B20: SORRENTO OYSTER | C20: Hide | D20: Active | E20: =SUMIFS('CPT Count'!$D:$D,'CPT Count'!$A:$A,$A20)-SUMIFS('Weekly Sales'!$F:$F,'Weekly Sales'!$H:$H,$A20,'Weekly Sales'!$I:$I,"CPT")+SUMIFS(Transfers!$F:$F,Transfers!$C:$C,$A20,Transfers!$J:$J,"CPT")-SUMIFS(Transfers!$F:$F,Transfers!$C:$C,$A20,Transfers!$I:$I,"CPT",Transfers!$H:$H,"<>Y")+SUMIFS('Stock Received'!$I:$I,'Stock Received'!$E:$E,$A20,'Stock Received'!$L:$L,"CPT") -> 0 | F20: =SUMIFS('JHB Count'!$E:$E,'JHB Count'!$F:$F,$A20)-SUMIFS('Weekly Sales'!$F:$F,'Weekly Sales'!$H:$H,$A20,'Weekly Sales'!$I:$I,"JHB")+SUMIFS(Transfers!$F:$F,Transfers!$C:$C,$A20,Transfers!$J:$J,"JHB")-SUMIFS(Transfers!$F:$F,Transfers!$C:$C,$A20,Transfers!$I:$I,"JHB",Transfers!$H:$H,"<>Y")+SUMIFS('Stock Received'!$I:$I,'Stock Received'!$E:$E,$A20,'Stock Received'!$L:$L,"JHB") -> 0 | G20: =SUMIFS('DBN Count'!$D:$D,'DBN Count'!$E:$E,$A20)-SUMIFS('Weekly Sales'!$F:$F,'Weekly Sales'!$H:$H,$A20,'Weekly Sales'!$I:$I,"DBN")+SUMIFS(Transfers!$F:$F,Transfers!$C:$C,$A20,Transfers!$J:$J,"DBN")-SUMIFS(Transfers!$F:$F,Transfers!$C:$C,$A20,Transfers!$I:$I,"DBN",Transfers!$H:$H,"<>Y")+SUMIFS('Stock Received'!$I:$I,'Stock Received'!$E:$E,$A20,'Stock Received'!$L:$L,"DBN") -> 0 | H20: =E20+F20+G20 -> 0 | I20: =SUMIFS('Weekly Sales'!$F:$F,'Weekly Sales'!$H:$H,$A20) -> 0 | J20: =SUMIFS(Orders!$L:$L,Orders!$D:$D,$A20,Orders!$F:$F,">="&J$4,Orders!$F:$F,"<"&EDATE(J$4,1)) -> 0 | K20: =SUMIFS(Orders!$L:$L,Orders!$D:$D,$A20,Orders!$F:$F,">="&K$4,Orders!$F:$F,"<"&EDATE(K$4,1)) -> 200 | L20: =SUMIFS(Orders!$L:$L,Orders!$D:$D,$A20,Orders!$F:$F,">="&L$4,Orders!$F:$F,"<"&EDATE(L$4,1)) -> 0 | M20: =N20-J20-K20-L20 -> 0 | N20: =SUMIFS(Orders!$L:$L,Orders!$D:$D,$A20) -> 200 | O20: =H20+N20 -> 200 | Q20: =IF(SUMIFS('Sales History'!$E:$E,'Sales History'!$G:$G,$A20)>0,SUMIFS('Sales History'!$E:$E,'Sales History'!$G:$G,$A20)/Settings!$B$4,N(P20)) -> 0 | R20: =IF(SUMIFS('Sales History'!$E:$E,'Sales History'!$G:$G,$A20)>0,"6-month history",IF(N(P20)>0,"Current sheet","No sales data")) -> No sales data | S20: =IF(Q20>0,H20/Q20,"") | U20: =IF(T20="","",MAX(0,T20-O20)) | V20: =IF(D20="End of range","END OF RANGE",IF(T20="","NO BUFFER SET",IF(H20<=0,IF(O20<T20,"OUT - REORDER","OUT - ON ORDER"),IF(O20<T20,"REORDER",IF(H20<T20,"LOW - ON ORDER",IF(AND(S20<>"",N(S20)>Settings!$B$5),"SLOW MOVER","OK")))))) -> NO BUFFER SET | X20: =IF(OR(D20="End of range",U20=""),0,IF(N(U20)>0,U20+ROW()/1000000,0)) -> 0
A21: SAN010 | B21: SANTOS ICE WHITE | C21: Hide | D21: Active | E21: =SUMIFS('CPT Count'!$D:$D,'CPT Count'!$A:$A,$A21)-SUMIFS('Weekly Sales'!$F:$F,'Weekly Sales'!$H:$H,$A21,'Weekly Sales'!$I:$I,"CPT")+SUMIFS(Transfers!$F:$F,Transfers!$C:$C,$A21,Transfers!$J:$J,"CPT")-SUMIFS(Transfers!$F:$F,Transfers!$C:$C,$A21,Transfers!$I:$I,"CPT",Transfers!$H:$H,"<>Y")+SUMIFS('Stock Received'!$I:$I,'Stock Received'!$E:$E,$A21,'Stock Received'!$L:$L,"CPT") -> 337.5 | F21: =SUMIFS('JHB Count'!$E:$E,'JHB Count'!$F:$F,$A21)-SUMIFS('Weekly Sales'!$F:$F,'Weekly Sales'!$H:$H,$A21,'Weekly Sales'!$I:$I,"JHB")+SUMIFS(Transfers!$F:$F,Transfers!$C:$C,$A21,Transfers!$J:$J,"JHB")-SUMIFS(Transfers!$F:$F,Transfers!$C:$C,$A21,Transfers!$I:$I,"JHB",Transfers!$H:$H,"<>Y")+SUMIFS('Stock Received'!$I:$I,'Stock Received'!$E:$E,$A21,'Stock Received'!$L:$L,"JHB") -> 80 | G21: =SUMIFS('DBN Count'!$D:$D,'DBN Count'!$E:$E,$A21)-SUMIFS('Weekly Sales'!$F:$F,'Weekly Sales'!$H:$H,$A21,'Weekly Sales'!$I:$I,"DBN")+SUMIFS(Transfers!$F:$F,Transfers!$C:$C,$A21,Transfers!$J:$J,"DBN")-SUMIFS(Transfers!$F:$F,Transfers!$C:$C,$A21,Transfers!$I:$I,"DBN",Transfers!$H:$H,"<>Y")+SUMIFS('Stock Received'!$I:$I,'Stock Received'!$E:$E,$A21,'Stock Received'!$L:$L,"DBN") -> 67.4 | H21: =E21+F21+G21 -> 484.9 | I21: =SUMIFS('Weekly Sales'!$F:$F,'Weekly Sales'!$H:$H,$A21) -> 0.5 | J21: =SUMIFS(Orders!$L:$L,Orders!$D:$D,$A21,Orders!$F:$F,">="&J$4,Orders!$F:$F,"<"&EDATE(J$4,1)) -> 0 | K21: =SUMIFS(Orders!$L:$L,Orders!$D:$D,$A21,Orders!$F:$F,">="&K$4,Orders!$F:$F,"<"&EDATE(K$4,1)) -> 300 | L21: =SUMIFS(Orders!$L:$L,Orders!$D:$D,$A21,Orders!$F:$F,">="&L$4,Orders!$F:$F,"<"&EDATE(L$4,1)) -> 0 | M21: =N21-J21-K21-L21 -> 0 | N21: =SUMIFS(Orders!$L:$L,Orders!$D:$D,$A21) -> 300 | O21: =H21+N21 -> 784.9 | P21: 150 | Q21: =IF(SUMIFS('Sales History'!$E:$E,'Sales History'!$G:$G,$A21)>0,SUMIFS('Sales History'!$E:$E,'Sales History'!$G:$G,$A21)/Settings!$B$4,N(P21)) -> 150 | R21: =IF(SUMIFS('Sales History'!$E:$E,'Sales History'!$G:$G,$A21)>0,"6-month history",IF(N(P21)>0,"Current sheet","No sales data")) -> Current sheet | S21: =IF(Q21>0,H21/Q21,"") -> 3.2326667 | T21: 300 | U21: =IF(T21="","",MAX(0,T21-O21)) -> 0 | V21: =IF(D21="End of range","END OF RANGE",IF(T21="","NO BUFFER SET",IF(H21<=0,IF(O21<T21,"OUT - REORDER","OUT - ON ORDER"),IF(O21<T21,"REORDER",IF(H21<T21,"LOW - ON ORDER",IF(AND(S21<>"",N(S21)>Settings!$B$5),"SLOW MOVER","OK")))))) -> OK | X21: =IF(OR(D21="End of range",U21=""),0,IF(N(U21)>0,U21+ROW()/1000000,0)) -> 0
A22: SAN006 | B22: SANTOS COTTON WHITE | C22: Hide | D22: Active | E22: =SUMIFS('CPT Count'!$D:$D,'CPT Count'!$A:$A,$A22)-SUMIFS('Weekly Sales'!$F:$F,'Weekly Sales'!$H:$H,$A22,'Weekly Sales'!$I:$I,"CPT")+SUMIFS(Transfers!$F:$F,Transfers!$C:$C,$A22,Transfers!$J:$J,"CPT")-SUMIFS(Transfers!$F:$F,Transfers!$C:$C,$A22,Transfers!$I:$I,"CPT",Transfers!$H:$H,"<>Y")+SUMIFS('Stock Received'!$I:$I,'Stock Received'!$E:$E,$A22,'Stock Received'!$L:$L,"CPT") -> 209.57 | F22: =SUMIFS('JHB Count'!$E:$E,'JHB Count'!$F:$F,$A22)-SUMIFS('Weekly Sales'!$F:$F,'Weekly Sales'!$H:$H,$A22,'Weekly Sales'!$I:$I,"JHB")+SUMIFS(Transfers!$F:$F,Transfers!$C:$C,$A22,Transfers!$J:$J,"JHB")-SUMIFS(Transfers!$F:$F,Transfers!$C:$C,$A22,Transfers!$I:$I,"JHB",Transfers!$H:$H,"<>Y")+SUMIFS('Stock Received'!$I:$I,'Stock Received'!$E:$E,$A22,'Stock Received'!$L:$L,"JHB") -> 0 | G22: =SUMIFS('DBN Count'!$D:$D,'DBN Count'!$E:$E,$A22)-SUMIFS('Weekly Sales'!$F:$F,'Weekly Sales'!$H:$H,$A22,'Weekly Sales'!$I:$I,"DBN")+SUMIFS(Transfers!$F:$F,Transfers!$C:$C,$A22,Transfers!$J:$J,"DBN")-SUMIFS(Transfers!$F:$F,Transfers!$C:$C,$A22,Transfers!$I:$I,"DBN",Transfers!$H:$H,"<>Y")+SUMIFS('Stock Received'!$I:$I,'Stock Received'!$E:$E,$A22,'Stock Received'!$L:$L,"DBN") -> 51.46 | H22: =E22+F22+G22 -> 261.03 | I22: =SUMIFS('Weekly Sales'!$F:$F,'Weekly Sales'!$H:$H,$A22) -> 9.43 | J22: =SUMIFS(Orders!$L:$L,Orders!$D:$D,$A22,Orders!$F:$F,">="&J$4,Orders!$F:$F,"<"&EDATE(J$4,1)) -> 0 | K22: =SUMIFS(Orders!$L:$L,Orders!$D:$D,$A22,Orders!$F:$F,">="&K$4,Orders!$F:$F,"<"&EDATE(K$4,1)) -> 300 | L22: =SUMIFS(Orders!$L:$L,Orders!$D:$D,$A22,Orders!$F:$F,">="&L$4,Orders!$F:$F,"<"&EDATE(L$4,1)) -> 0 | M22: =N22-J22-K22-L22 -> 0 | N22: =SUMIFS(Orders!$L:$L,Orders!$D:$D,$A22) -> 300 | O22: =H22+N22 -> 561.03 | P22: 80 | Q22: =IF(SUMIFS('Sales History'!$E:$E,'Sales History'!$G:$G,$A22)>0,SUMIFS('Sales History'!$E:$E,'Sales History'!$G:$G,$A22)/Settings!$B$4,N(P22)) -> 80 | R22: =IF(SUMIFS('Sales History'!$E:$E,'Sales History'!$G:$G,$A22)>0,"6-month history",IF(N(P22)>0,"Current sheet","No sales data")) -> Current sheet | S22: =IF(Q22>0,H22/Q22,"") -> 3.262875 | T22: 200 | U22: =IF(T22="","",MAX(0,T22-O22)) -> 0 | V22: =IF(D22="End of range","END OF RANGE",IF(T22="","NO BUFFER SET",IF(H22<=0,IF(O22<T22,"OUT - REORDER","OUT - ON ORDER"),IF(O22<T22,"REORDER",IF(H22<T22,"LOW - ON ORDER",IF(AND(S22<>"",N(S22)>Settings!$B$5),"SLOW MOVER","OK")))))) -> OK | X22: =IF(OR(D22="End of range",U22=""),0,IF(N(U22)>0,U22+ROW()/1000000,0)) -> 0
